Workbook

Sheet Dashboard
B1: Dashboard — Recebimentos 1º Semestre 2026
B2: Distribuidora Aurora Ltda · Janeiro a Junho de 2026 · Fonte: aba Recebimentos
B4: Total Recebido no Semestre | D4: Número de Recebimentos | F4: Ticket Médio | H4: Melhor Mês | J4: Maior Cliente
B5: =SUM(Recebimentos!$C$5:$C$224) -> 4200174.2 | D5: =COUNT(Recebimentos!$C$5:$C$224) -> 220 | F5: =IFERROR(B5/D5,0) -> 19091.701 | H5: =INDEX($A$61:$A$66,MATCH(MAX($B$61:$B$66),$B$61:$B$66,0)) -> Abril | J5: =INDEX($A$92:$A$105,MATCH(MAX($B$92:$B$105),$B$92:$B$105,0)) -> Supermercado Familia
H6: =MAX($B$61:$B$66) -> 864938.31 | J6: =MAX($B$92:$B$105) -> 1149147.3
A59: Tabelas de apoio aos gráficos do Dashboard (fora da área de impressão — não ocultar)
A60: Mês | B60: Valor (R$)
A61: Janeiro | B61: =SUMPRODUCT((MONTH(Recebimentos!$A$5:$A$224)=1)*(YEAR(Recebimentos!$A$5:$A$224)=2026)*Recebimentos!$C$5:$C$224) -> 625659.11
A62: Fevereiro | B62: =SUMPRODUCT((MONTH(Recebimentos!$A$5:$A$224)=2)*(YEAR(Recebimentos!$A$5:$A$224)=2026)*Recebimentos!$C$5:$C$224) -> 661449.66
A63: Março | B63: =SUMPRODUCT((MONTH(Recebimentos!$A$5:$A$224)=3)*(YEAR(Recebimentos!$A$5:$A$224)=2026)*Recebimentos!$C$5:$C$224) -> 719121.93
A64: Abril | B64: =SUMPRODUCT((MONTH(Recebimentos!$A$5:$A$224)=4)*(YEAR(Recebimentos!$A$5:$A$224)=2026)*Recebimentos!$C$5:$C$224) -> 864938.31
A65: Maio | B65: =SUMPRODUCT((MONTH(Recebimentos!$A$5:$A$224)=5)*(YEAR(Recebimentos!$A$5:$A$224)=2026)*Recebimentos!$C$5:$C$224) -> 587578.29
A66: Junho | B66: =SUMPRODUCT((MONTH(Recebimentos!$A$5:$A$224)=6)*(YEAR(Recebimentos!$A$5:$A$224)=2026)*Recebimentos!$C$5:$C$224) -> 741426.85
A69: Região/UF | B69: Valor (R$)
A70: Norte/PA | B70: =SUMIF(Recebimentos!$E$5:$E$224,A70,Recebimentos!$C$5:$C$224) -> 1149147.3
A71: Sudeste/SP | B71: =SUMIF(Recebimentos!$E$5:$E$224,A71,Recebimentos!$C$5:$C$224) -> 948100.78
A72: Nordeste/PE | B72: =SUMIF(Recebimentos!$E$5:$E$224,A72,Recebimentos!$C$5:$C$224) -> 885660.97
A73: Centro-Oeste/GO | B73: =SUMIF(Recebimentos!$E$5:$E$224,A73,Recebimentos!$C$5:$C$224) -> 494431.98
A74: Sul/RS | B74: =SUMIF(Recebimentos!$E$5:$E$224,A74,Recebimentos!$C$5:$C$224) -> 387431.18
A75: Nordeste/CE | B75: =SUMIF(Recebimentos!$E$5:$E$224,A75,Recebimentos!$C$5:$C$224) -> 143941.92
A76: Centro-Oeste/MT | B76: =SUMIF(Recebimentos!$E$5:$E$224,A76,Recebimentos!$C$5:$C$224) -> 84883.24
A77: Não identificado | B77: =SUMPRODUCT((Recebimentos!$E$5:$E$224="")*Recebimentos!$C$5:$C$224) -> 58209.18
A78: Sul/PR | B78: =SUMIF(Recebimentos!$E$5:$E$224,A78,Recebimentos!$C$5:$C$224) -> 42199.5
A79: Norte/AM | B79: =SUMIF(Recebimentos!$E$5:$E$224,A79,Recebimentos!$C$5:$C$224) -> 6168.09
A82: Categoria | B82: Valor (R$)
A83: Hortifruti | B83: =SUMIF(Recebimentos!$F$5:$F$224,A83,Recebimentos!$C$5:$C$224) -> 1643579.3
A84: Bebidas | B84: =SUMIF(Recebimentos!$F$5:$F$224,A84,Recebimentos!$C$5:$C$224) -> 1273092.1
A85: Mercearia | B85: =SUMIF(Recebimentos!$F$5:$F$224,A85,Recebimentos!$C$5:$C$224) -> 882844.33
A86: Congelados | B86: =SUMIF(Recebimentos!$F$5:$F$224,A86,Recebimentos!$C$5:$C$224) -> 294081.61
A87: Não identificado | B87: =SUMPRODUCT((Recebimentos!$F$5:$F$224="")*Recebimentos!$C$5:$C$224) -> 58209.18
A88: Higiene e Limpeza | B88: =SUMIF(Recebimentos!$F$5:$F$224,A88,Recebimentos!$C$5:$C$224) -> 48367.59
A91: Cliente | B91: Valor (R$)
A92: Supermercado Familia | B92: =SUMIF(Recebimentos!$B$5:$B$224,A92,Recebimentos!$C$5:$C$224) -> 1149147.3
A93: Adega Ponto do Vinho | B93: =SUMIF(Recebimentos!$B$5:$B$224,A93,Recebimentos!$C$5:$C$224) -> 885660.97
A94: Atacado Uniao Comercial | B94: =SUMIF(Recebimentos!$B$5:$B$224,A94,Recebimentos!$C$5:$C$224) -> 738902.41
A95: Hortifruti Natural | B95: =SUMIF(Recebimentos!$B$5:$B$224,A95,Recebimentos!$C$5:$C$224) -> 494431.98
A96: Distribuidora Bebidas Lopes | B96: =SUMIF(Recebimentos!$B$5:$B$224,A96,Recebimentos!$C$5:$C$224) -> 387431.18
A97: Rede Supermercados Mais | B97: =SUMIF(Recebimentos!$B$5:$B$224,A97,Recebimentos!$C$5:$C$224) -> 209198.37
A98: Mercadao Central | B98: =SUMIF(Recebimentos!$B$5:$B$224,A98,Recebimentos!$C$5:$C$224) -> 143941.92
A99: Frigorifico Vale Verde | B99: =SUMIF(Recebimentos!$B$5:$B$224,A99,Recebimentos!$C$5:$C$224) -> 84883.24
...

Sheet Recebimentos
A1: Distribuidora Aurora Ltda - Controle de Recebimentos
A2: 1o semestre de 2026 (janeiro a junho)
A4: Data | B4: Cliente | C4: Valor (R$) | D4: Forma de Pagamento | E4: Regiao/UF | F4: Categoria
A5: 46023 | B5: Atacado Uniao Comercial | C5: 19870 | D5: Boleto | E5: Sudeste/SP | F5: Mercearia
A6: 46027 | B6: Supermercado Familia | C6: 14870 | D6: Boleto | E6: Norte/PA | F6: Hortifruti
A7: 46028 | B7: Hortifruti Natural | C7: 32588.48 | D7: Pix | E7: Centro-Oeste/GO | F7: Hortifruti
A8: 46030 | B8: Distribuidora Bebidas Lopes | C8: 21750 | D8: Pix | E8: Sul/RS | F8: Bebidas
A9: 46033 | B9: Adega Ponto do Vinho | C9: 51323.96 | D9: Boleto | E9: Nordeste/PE | F9: Bebidas
A10: 46034 | B10: Hortifruti Natural | C10: 5350 | D10: Deposito | E10: Centro-Oeste/GO | F10: Hortifruti
A11: 46035 | B11: Rede Farmacias Popular | C11: 8179.8 | D11: Boleto | E11: Sul/PR | F11: Higiene e Limpeza
A12: 46035 | B12: Atacado Uniao Comercial | C12: 18200 | D12: Boleto | E12: Sudeste/SP | F12: Mercearia
A13: 46035 | B13: Supermercado Familia | C13: 12800 | D13: Pix | E13: Norte/PA | F13: Hortifruti
A14: 46035 | B14: Supermercado Familia | C14: 17910 | D14: Boleto | E14: Norte/PA | F14: Hortifruti
A15: 46035 | B15: Rede Supermercados Mais | C15: 41510 | D15: Pix | E15: Sudeste/SP | F15: Congelados
A16: 46036 | B16: Mercadao Central | C16: 6510 | D16: Pix | E16: Nordeste/CE | F16: Mercearia
... A42: 46058 | B42: Distribuidora Bebidas Lopes | C42: 14980 | D42: Boleto | E42: Sul/RS | F42: Bebidas
A43: 46059 | B43: Padaria e Confeitaria Trigo de Ouro | C43: 8330 | D43: Deposito
A44: 46062 | B44: Frigorifico Vale Verde | C44: 6280 | D44: Pix | E44: Centro-Oeste/MT | F44: Congelados
A45: 46064 | B45: Bar e Restaurante Estrela do Sul | C45: 7040 | D45: Pix
A46: 46065 | B46: Atacado Uniao Comercial | C46: 22930 | D46: Pix | E46: Sudeste/SP | F46: Mercearia
A47: 46066 | B47: Supermercado Familia | C47: 14580 | D47: Boleto | E47: Norte/PA | F47: Hortifruti
A48: 46066 | B48: Rede Supermercados Mais | C48: 13198.52 | D48: Pix | E48: Sudeste/SP | F48: Congelados
A49: 46066 | B49: Distribuidora Bebidas Lopes | C49: 29770 | D49: Pix | E49: Sul/RS | F49: Bebidas
A50: 46068 | B50: Frigorifico Vale Verde | C50: 4740 | D50: Pix | E50: Centro-Oeste/MT | F50: Congelados
A51: 46068 | B51: Supermercado Familia | C51: 9226.7 | D51: Transferencia | E51: Norte/PA | F51: Hortifruti
A52: 46069 | B52: Supermercado Familia | C52: 20420 | D52: Boleto | E52: Norte/PA | F52: Hortifruti
A53: 46069 | B53: Hortifruti Natural | C53: 9270 | D53: Deposito | E53: Centro-Oeste/GO | F53: Hortifruti
A54: 46070 | B54: Adega Ponto do Vinho | C54: 9730 | D54: Boleto | E54: Nordeste/PE | F54: Bebidas
A55: 46070 | B55: Hortifruti Natural | C55: 13759.65 | D55: Boleto | E55: Centro-Oeste/GO | F55: Hortifruti
A56: 46070 | B56: Supermercado Familia | C56: 12990 | D56: Boleto | E56: Norte/PA | F56: Hortifruti
A57: 46070 | B57: Atacado Uniao Comercial | C57: 65960 | D57: TED | E57: Sudeste/SP | F57: Mercearia
... A87: 46097 | B87: Rede Farmacias Popular | C87: 8650 | D87: Deposito | E87: Sul/PR | F87: Higiene e Limpeza
A88: 46098 | B88: Emporio Vila Nova Ltda | C88: 22271.71 | D88: Boleto
A89: 46098 | B89: Frigorifico Vale Verde | C89: 7260 | D89: Boleto | E89: Centro-Oeste/MT | F89: Congelados
A90: 46101 | B90: Adega Ponto do Vinho | C90: 30356.99 | D90: Pix | E90: Nordeste/PE | F90: Bebidas
A91: 46104 | B91: Frigorifico Vale Verde | C91: 5330 | D91: Boleto | E91: Centro-Oeste/MT | F91: Congelados
A92: 46104 | B92: Hortifruti Natural | C92: 31290 | D92: Deposito | E92: Centro-Oeste/GO | F92: Hortifruti
A93: 46104 | B93: Comercial Amazonas | C93: 380 | D93: Pix | E93: Norte/AM | F93: Higiene e Limpeza
A94: 46105 | B94: Adega Ponto do Vinho | C94: 18260 | D94: Pix | E94: Nordeste/PE | F94: Bebidas
A95: 46105 | B95: Adega Ponto do Vinho | C95: 7336.41 | D95: Pix | E95: Nordeste/PE | F95: Bebidas
...

Sheet Cadastro de Clientes
A1: Cadastro de Clientes
A2: Base cadastral da Aurora
A4: Cliente | B4: Regiao/UF | C4: Categoria
A5: Adega Ponto do Vinho | B5: Nordeste/PE | C5: Bebidas
A6: Atacado Uniao Comercial | B6: Sudeste/SP | C6: Mercearia
A7: Comercial Amazonas | B7: Norte/AM | C7: Higiene e Limpeza
A8: Distribuidora Bebidas Lopes | B8: Sul/RS | C8: Bebidas
A9: Frigorifico Vale Verde | B9: Centro-Oeste/MT | C9: Congelados
A10: Hortifruti Natural | B10: Centro-Oeste/GO | C10: Hortifruti
A11: Mercadao Central | B11: Nordeste/CE | C11: Mercearia
A12: Rede Farmacias Popular | B12: Sul/PR | C12: Higiene e Limpeza
A13: Rede Supermercados Mais | B13: Sudeste/SP | C13: Congelados
A14: Supermercado Familia | B14: Norte/PA | C14: Hortifruti
